Workbook

Sheet Metodologia
B2: Coeficiente de Gini y Deciles - IPCF - Aglomerado Corrientes (EPH-INDEC)
B4: Variables utilizadas y por que
B5: IPCF | C5: Ingreso Per Capita Familiar. Variable estandar para medir desigualdad entre personas: divide el ingreso del hogar por su cantidad de miembros, permitiendo comparar hogares de distinto tamano.
B7: PONDIH | C7: Ponderador de ingreso per capita familiar (distinto de PONDERA, que es el ponderador demografico general). Es el que corresponde usar para IPCF/ITF segun el Anexo I del INDEC, ya que esta ajustado por no respuesta de ingresos.
B9: DECCFR | C9: Decil de IPCF calculado por INDEC a NIVEL NACIONAL. Aqui se usa unicamente como FILTRO de calidad de dato: se descartan los codigos 0 y 12 (hogar sin ingreso declarado / no responde). NO se usa para clasificar los deciles del grafico, porque clasificaria a los hogares de Corrientes contra la distribucion de TODO el pais, no contra si mismos (ver mas abajo).
B11: AGLOMERADO | C11: Codigo de aglomerado urbano de la EPH. Corrientes = codigo 12. Se filtra el universo a este aglomerado exclusivamente, segun lo definido con la catedra.
B14: Por que deciles LOCALES y no DECCFR directo
C15: DECCFR clasifica a cada hogar segun su posicion en la distribucion de ingresos de TODO EL PAIS. Si quisieramos ver como se reparte el ingreso dentro de Corrientes, usar DECCFR tal cual generaria deciles desbalanceados (por ejemplo, la mayoria de los hogares de Corrientes podria caer en los deciles bajos nacionales, dejando pocos o ningun caso en los deciles altos). Por eso se recalculan deciles LOCALES: se ordena a la poblacion de Corrientes por IPCF de menor a mayor y se corta en 10 grupos de igual tamano poblacional (ponderado por PONDIH), igual que hace INDEC pero restringido al aglomerado. Este calculo se hace en la columna I de las hojas Gini_T4_2024 y Gini_T4_2025, reutilizando la poblacion acumulada ya calculada para el Gini.
B17: Filtro aplicado
C18: AGLOMERADO = 12 (Corrientes) y DECCFR entre 1 y 10 (se excluyen los hogares sin ingreso declarado / no respuesta, codigos 0 y 12, que no reflejan pobreza real sino falta de dato).
B20: Como se agregaron los datos
C21: El IPCF se repite para todos los integrantes de un mismo hogar. Se agrupo por valor de IPCF sumando el PONDIH correspondiente, sin perder precision, para que la tabla sea manejable en Excel.
B23: Formula del Gini (metodo trapezoidal / Curva de Lorenz)
C24: 1) Se ordena el IPCF de menor a mayor. 2) Se calcula la poblacion acumulada (X) y el ingreso acumulado (Y) como proporcion del total. 3) Gini = 1 - Sum (X_i - X_(i-1)) x (Y_i + Y_(i-1)). Un Gini de 0 = igualdad perfecta; un Gini de 1 = desigualdad maxima.

Sheet Resumen
A1: Desigualdad de ingresos - Aglomerado Corrientes
A2: EPH-INDEC, 4to Trimestre 2024 vs 4to Trimestre 2025
A4: Coeficiente de Gini
A5: Periodo | B5: Gini
A6: 4to Trimestre 2024 | B6: =Gini_T4_2024!C269 -> 0.33057067
A7: 4to Trimestre 2025 | B7: =Gini_T4_2025!C225 -> 0.33580539
A8: Variacion | B8: =B7-B6 -> 0.0052347181
A11: Brechas entre deciles
A12: Indicador | B12: T4 2024 | C12: T4 2025 | D12: Variacion
A13: D10 / D1 | B13: =Deciles_T4_2024!C16 -> 8.7754045 | C13: =Deciles_T4_2025!C16 -> 9.8275907 | D13: =C13-B13 -> 1.0521862
A14: D9 / D1 | B14: =Deciles_T4_2024!C17 -> 5.1393581 | C14: =Deciles_T4_2025!C17 -> 6.4677665 | D14: =C14-B14 -> 1.3284084
A15: D10 / D5 | B15: =Deciles_T4_2024!C18 -> 3.4807986 | C15: =Deciles_T4_2025!C18 -> 3.067654 | D15: =C15-B15 -> -0.41314459
A16: % ingreso del decil mas rico (D10) | B16: =Deciles_T4_2024!C19 -> 0.26225759 | C16: =Deciles_T4_2025!C19 -> 0.24703747 | D16: =C16-B16 -> -0.015220123
A17: % ingreso del decil mas pobre (D1) | B17: =Deciles_T4_2024!C20 -> 0.029014987 | C17: =Deciles_T4_2025!C20 -> 0.024600405 | D17: =C17-B17 -> -0.0044145823
A30: Datos para Curva de Lorenz (acumulado por decil)
A31: Decil (0=origen) | B31: % Poblacion acumulada | C31: % Ingreso acum. T4 2024 | D31: % Ingreso acum. T4 2025 | E31: Linea de igualdad
A32: 0 | B32: 0 | C32: 0 | D32: 0 | E32: 0
A33: 1 | B33: 0.1 | C33: =SUM(Deciles_T4_2024!$E$2) -> 0.029014987 | D33: =SUM(Deciles_T4_2025!$E$2) -> 0.024600405 | E33: 0.1
A34: 2 | B34: 0.2 | C34: =SUM(Deciles_T4_2024!$E$2:$E$3) -> 0.072713353 | D34: =SUM(Deciles_T4_2025!$E$2:$E$3) -> 0.063940609 | E34: 0.2
A35: 3 | B35: 0.3 | C35: =SUM(Deciles_T4_2024!$E$2:$E$4) -> 0.13575708 | D35: =SUM(Deciles_T4_2025!$E$2:$E$4) -> 0.11959523 | E35: 0.3
A36: 4 | B36: 0.4 | C36: =SUM(Deciles_T4_2024!$E$2:$E$5) -> 0.19789001 | D36: =SUM(Deciles_T4_2025!$E$2:$E$5) -> 0.1880586 | E36: 0.4
A37: 5 | B37: 0.5 | C37: =SUM(Deciles_T4_2024!$E$2:$E$6) -> 0.27542312 | D37: =SUM(Deciles_T4_2025!$E$2:$E$6) -> 0.26118125 | E37: 0.5
A38: 6 | B38: 0.6 | C38: =SUM(Deciles_T4_2024!$E$2:$E$7) -> 0.36199816 | D38: =SUM(Deciles_T4_2025!$E$2:$E$7) -> 0.35172938 | E38: 0.6
A39: 7 | B39: 0.7 | C39: =SUM(Deciles_T4_2024!$E$2:$E$8) -> 0.46428293 | D39: =SUM(Deciles_T4_2025!$E$2:$E$8) -> 0.4644909 | E39: 0.7
A40: 8 | B40: 0.8 | C40: =SUM(Deciles_T4_2024!$E$2:$E$9) -> 0.58563746 | D40: =SUM(Deciles_T4_2025!$E$2:$E$9) -> 0.59501807 | E40: 0.8
A41: 9 | B41: 0.9 | C41: =SUM(Deciles_T4_2024!$E$2:$E$10) -> 0.73774241 | D41: =SUM(Deciles_T4_2025!$E$2:$E$10) -> 0.75296253 | E41: 0.9
A42: 10 | B42: 1 | C42: =SUM(Deciles_T4_2024!$E$2:$E$11) -> 1 | D42: =SUM(Deciles_T4_2025!$E$2:$E$11) -> 1 | E42: 1
A44: Ingreso promedio (IPCF) por decil
A45: Decil | B45: T4 2024 | C45: T4 2025
A46: 1 | B46: =Deciles_T4_2024!D2 -> 99450.647 | C46: =Deciles_T4_2025!D2 -> 109085.18
A47: 2 | B47: =Deciles_T4_2024!D3 -> 156387.49 | C47: =Deciles_T4_2025!D3 -> 184462.7
A48: 3 | B48: =Deciles_T4_2024!D4 -> 197580.35 | C48: =Deciles_T4_2025!D4 -> 243511.78
A49: 4 | B49: =Deciles_T4_2024!D5 -> 221641.51 | C49: =Deciles_T4_2025!D5 -> 291700.12
A50: 5 | B50: =Deciles_T4_2024!D6 -> 250723.97 | C50: =Deciles_T4_2025!D6 -> 349467.21
A51: 6 | B51: =Deciles_T4_2024!D7 -> 297041.4 | C51: =Deciles_T4_2025!D7 -> 397317.73
A52: 7 | B52: =Deciles_T4_2024!D8 -> 347677.72 | C52: =Deciles_T4_2025!D8 -> 479657.62
A53: 8 | B53: =Deciles_T4_2024!D9 -> 398599.89 | C53: =Deciles_T4_2025!D9 -> 565244.59
A54: 9 | B54: =Deciles_T4_2024!D10 -> 511112.49 | C54: =Deciles_T4_2025!D10 -> 705537.46
A55: 10 | B55: =Deciles_T4_2024!D11 -> 872719.66 | C55: =Deciles_T4_2025!D11 -> 1072044.5
A57: Evolucion del Gini | B57: Gini
...

Sheet Comparacion_INDEC
A1: Comparación con datos oficiales del INDEC
A2: Coeficiente de Gini del aglomerado/provincia Corrientes vs. Total Nacional Urbano
A4: 1) Gini Nacional (31 aglomerados urbanos) - series trimestral oficial INDEC
A5: Periodo | B5: Gini Grupo 5 (aglomerado Corrientes) | C5: Gini INDEC (Total Nacional Urbano) | D5: Diferencia
A6: 4to Trimestre 2024 | B6: =Resumen!B6 -> 0.33057067 | C6: 0.43 | D6: =B6-C6 -> -0.099429326
A7: 4to Trimestre 2025 | B7: =Resumen!B7 -> 0.33580539 | C7: 0.427 | D7: =B7-C7 -> -0.091194608
A9: Nota: este Gini nacional agrega los 31 aglomerados urbanos del país (incluye CABA, GBA, etc.). No es directamente comparable con un Gini calculado solo para el aglomerado Corrientes: es esperable que un aglomerado individual tenga un nivel de desigualdad distinto al promedio nacional.
A12: 2) Gini por provincia (EPH Total Urbano) - informe anual oficial INDEC, en base al 3er trimestre
A13: Periodo (INDEC = 3er trim.) | B13: Gini Grupo 5 (aglomerado Corrientes, 4to trim. mismo año) | C13: Gini INDEC (provincia Corrientes, total urbano) | D13: Diferencia
A14: 2023 / 2024 | B14: =Resumen!B6 -> 0.33057067 | C14: 0.421 | D14: =B14-C14 -> -0.090429326
A15: 2025 | B15: =Resumen!B7 -> 0.33580539 | C15: 0.351 | D15: =B15-C15 -> -0.015194608
A17: Nota: este es el dato oficial más cercano geográficamente al calculado por el Grupo 5, pero con dos diferencias metodológicas importantes: (a) el INDEC mide la PROVINCIA de Corrientes (aglomerado + "resto urbano", localidades chicas), no solo el aglomerado/ciudad capital; y (b) el INDEC releva este dato una vez al año, en el 3er trimestre, mientras que nuestro cálculo usa el 4to trimestre. Por eso los períodos no son exactamente los mismos.
A21: 3) Conclusiones de la comparación
A22: - El Gini del aglomerado Corrientes calculado por el Grupo 5 (~0,33) es sensiblemente menor al Gini nacional de 31 aglomerados (~0,43). Esto es esperable: el indicador nacional agrega jurisdicciones con mucha mayor desigualdad (ej. CABA, Buenos Aires) y no debería coincidir con el de un aglomerado del interior.
A25: - La comparación más cercana en términos geográficos es la del Gini provincial de Corrientes que publica el INDEC una vez al año (0,421 en 2023 y 0,351 en 2025). El valor de 2025 (0,351) es del mismo orden de magnitud que el calculado por el grupo para T4 2025 (0,3358), aunque no idéntico por las diferencias de trimestre y de cobertura geográfica explicadas arriba.
A28: - Se observa una diferencia de tendencia que vale la pena mencionar como limitación: el INDEC muestra una fuerte CAÍDA del Gini provincial entre 2023 y 2025, mientras que el cálculo del grupo muestra un leve AUMENTO entre T4 2024 y T4 2025. Esto puede deberse a la diferencia de trimestre/cobertura geográfica, y no debe interpretarse como un error de cálculo sin antes profundizar el análisis.
A31: - Conclusión: los valores del Grupo 5 son plausibles y del orden de magnitud correcto, pero no son directamente comparables con la cifra nacional del INDEC ni 100% equivalentes a la cifra provincial (distinta cobertura geográfica y distinto trimestre de referencia).

Sheet Gini_T4_2024
A1: IPCF | B1: PONDIH (peso) | C1: Ingreso total (IPCF x PONDIH) | D1: Poblacion acumulada | E1: Ingreso acumulado | F1: % Poblacion acum. (X) | G1: % Ingreso acum. (Y) | H1: Termino trapezoide | I1: Decil local (Corrientes)
A2: 0 | B2: 0 | C2: 0 | D2: 0 | E2: 0 | F2: 0 | G2: 0 | H2: 0 | I2: 0
A3: 53166.67 | B3: 2340 | C3: =A3*B3 -> 1.2441001e+08 | D3: =SUM($B$3:B3) -> 2340 | E3: =SUM($C$3:C3) -> 1.2441001e+08 | F3: =D3/$D$266 -> 0.0059596425 | G3: =E3/$E$266 -> 0.00094043285 | H3: =(F3-F2)*(G3+G2) -> 5.6046436e-06 | I3: =MIN(10,ROUNDUP(F3*10,0)) -> 1
A4: 65428.57 | B4: 1995 | C4: =A4*B4 -> 1.3053e+08 | D4: =SUM($B$3:B4) -> 4335 | E4: =SUM($C$3:C4) -> 2.5494e+08 | F4: =D4/$D$266 -> 0.01104062 | G4: =E4/$E$266 -> 0.0019271276 | H4: =(F4-F3)*(G4+G3) -> 1.4570009e-05 | I4: =MIN(10,ROUNDUP(F4*10,0)) -> 1
A5: 66666.67 | B5: 1128 | C5: =A5*B5 -> 75200004 | D5: =SUM($B$3:B5) -> 5463 | E5: =SUM($C$3:C5) -> 3.3014001e+08 | F5: =D5/$D$266 -> 0.013913473 | G5: =E5/$E$266 -> 0.002495575 | H5: =(F5-F4)*(G5+G4) -> 1.2705776e-05 | I5: =MIN(10,ROUNDUP(F5*10,0)) -> 1
A6: 68333.33 | B6: 1233 | C6: =A6*B6 -> 84254996 | D6: =SUM($B$3:B6) -> 6696 | E6: =SUM($C$3:C6) -> 4.14395e+08 | F6: =D6/$D$266 -> 0.017053746 | G6: =E6/$E$266 -> 0.0031324705 | H6: =(F6-F5)*(G6+G5) -> 1.76736e-05 | I6: =MIN(10,ROUNDUP(F6*10,0)) -> 1
A7: 70000 | B7: 1868 | C7: =A7*B7 -> 130760000 | D7: =SUM($B$3:B7) -> 8564 | E7: =SUM($C$3:C7) -> 5.45155e+08 | F7: =D7/$D$266 -> 0.021811273 | G7: =E7/$E$266 -> 0.0041209038 | H7: =(F7-F6)*(G7+G6) -> 3.4508121e-05 | I7: =MIN(10,ROUNDUP(F7*10,0)) -> 1
A8: 79500 | B8: 1428 | C8: =A8*B8 -> 113526000 | D8: =SUM($B$3:B8) -> 9992 | E8: =SUM($C$3:C8) -> 6.58681e+08 | F8: =D8/$D$266 -> 0.025448183 | G8: =E8/$E$266 -> 0.0049790629 | H8: =(F8-F7)*(G8+G7) -> 3.309576e-05 | I8: =MIN(10,ROUNDUP(F8*10,0)) -> 1
A9: 86000 | B9: 1023 | C9: =A9*B9 -> 87978000 | D9: =SUM($B$3:B9) -> 11015 | E9: =SUM($C$3:C9) -> 7.46659e+08 | F9: =D9/$D$266 -> 0.028053616 | G9: =E9/$E$266 -> 0.005644101 | H9: =(F9-F8)*(G9+G8) -> 2.7677947e-05 | I9: =MIN(10,ROUNDUP(F9*10,0)) -> 1
A10: 88403.5 | B10: 1862 | C10: =A10*B10 -> 164607317 | D10: =SUM($B$3:B10) -> 12877 | E10: =SUM($C$3:C10) -> 9.1126632e+08 | F10: =D10/$D$266 -> 0.032795862 | G10: =E10/$E$266 -> 0.006888391 | H10: =(F10-F9)*(G10+G9) -> 5.9432153e-05 | I10: =MIN(10,ROUNDUP(F10*10,0)) -> 1
A11: 90000 | B11: 3696 | C11: =A11*B11 -> 332640000 | D11: =SUM($B$3:B11) -> 16573 | E11: =SUM($C$3:C11) -> 1.2439063e+09 | F11: =D11/$D$266 -> 0.042209041 | G11: =E11/$E$266 -> 0.0094028638 | H11: =(F11-F10)*(G11+G10) -> 0.0001533525 | I11: =MIN(10,ROUNDUP(F11*10,0)) -> 1
A12: 93750 | B12: 1572 | C12: =A12*B12 -> 147375000 | D12: =SUM($B$3:B12) -> 18145 | E12: =SUM($C$3:C12) -> 1.3912813e+09 | F12: =D12/$D$266 -> 0.046212698 | G12: =E12/$E$266 -> 0.010516892 | H12: =(F12-F11)*(G12+G11) -> 7.9751877e-05 | I12: =MIN(10,ROUNDUP(F12*10,0)) -> 1
A13: 99000 | B13: 600 | C13: =A13*B13 -> 59400000 | D13: =SUM($B$3:B13) -> 18745 | E13: =SUM($C$3:C13) -> 1.4506813e+09 | F13: =D13/$D$266 -> 0.047740812 | G13: =E13/$E$266 -> 0.010965905 | H13: =(F13-F12)*(G13+G12) -> 3.2828152e-05 | I13: =MIN(10,ROUNDUP(F13*10,0)) -> 1
A14: 102125 | B14: 518 | C14: =A14*B14 -> 52900750 | D14: =SUM($B$3:B14) -> 19263 | E14: =SUM($C$3:C14) -> 1.5035821e+09 | F14: =D14/$D$266 -> 0.049060083 | G14: =E14/$E$266 -> 0.01136579 | H14: =(F14-F13)*(G14+G13) -> 2.9461564e-05 | I14: =MIN(10,ROUNDUP(F14*10,0)) -> 1
... A266: 2303711.2 | B266: 976 | C266: =A266*B266 -> 2248422180 | D266: =SUM($B$3:B266) -> 392641 | E266: =SUM($C$3:C266) -> 1.3229016e+11 | F266: =D266/$D$266 -> 1 | G266: =E266/$E$266 -> 1 | H266: =(F266-F265)*(G266+G265) -> 0.0049292146 | I266: =MIN(10,ROUNDUP(F266*10,0)) -> 10
A268: Suma terminos trapezoide (Sum H) | C268: =SUM(H3:H266) -> 0.66942933
A269: COEFICIENTE DE GINI | C269: =1-C268 -> 0.33057067

Sheet Gini_T4_2025
A1: IPCF | B1: PONDIH (peso) | C1: Ingreso total (IPCF x PONDIH) | D1: Poblacion acumulada | E1: Ingreso acumulado | F1: % Poblacion acum. (X) | G1: % Ingreso acum. (Y) | H1: Termino trapezoide | I1: Decil local (Corrientes)
A2: 0 | B2: 0 | C2: 0 | D2: 0 | E2: 0 | F2: 0 | G2: 0 | H2: 0 | I2: 0
A3: 26000 | B3: 1296 | C3: =A3*B3 -> 33696000 | D3: =SUM($B$3:B3) -> 1296 | E3: =SUM($C$3:C3) -> 33696000 | F3: =D3/$D$222 -> 0.003277793 | G3: =E3/$E$222 -> 0.00019255941 | H3: =(F3-F2)*(G3+G2) -> 6.3116989e-07 | I3: =MIN(10,ROUNDUP(F3*10,0)) -> 1
A4: 46000 | B4: 1359 | C4: =A4*B4 -> 62514000 | D4: =SUM($B$3:B4) -> 2655 | E4: =SUM($C$3:C4) -> 96210000 | F4: =D4/$D$222 -> 0.0067149231 | G4: =E4/$E$222 -> 0.00054980239 | H4: =(F4-F3)*(G4+G3) -> 2.5515941e-06 | I4: =MIN(10,ROUNDUP(F4*10,0)) -> 1
A5: 73018 | B5: 326 | C5: =A5*B5 -> 23803868 | D5: =SUM($B$3:B5) -> 2981 | E5: =SUM($C$3:C5) -> 120013868 | F5: =D5/$D$222 -> 0.0075394296 | G5: =E5/$E$222 -> 0.00068583215 | H5: =(F5-F4)*(G5+G4) -> 1.0187888e-06 | I5: =MIN(10,ROUNDUP(F5*10,0)) -> 1
A6: 76226.29 | B6: 2576 | C6: =A6*B6 -> 1.9635892e+08 | D6: =SUM($B$3:B6) -> 5557 | E6: =SUM($C$3:C6) -> 3.1637279e+08 | F6: =D6/$D$222 -> 0.014054549 | G6: =E6/$E$222 -> 0.0018079463 | H6: =(F6-F5)*(G6+G5) -> 1.6247264e-05 | I6: =MIN(10,ROUNDUP(F6*10,0)) -> 1
A7: 91053.67 | B7: 1884 | C7: =A7*B7 -> 1.7154511e+08 | D7: =SUM($B$3:B7) -> 7441 | E7: =SUM($C$3:C7) -> 4.8791791e+08 | F7: =D7/$D$222 -> 0.018819489 | G7: =E7/$E$222 -> 0.0027882593 | H7: =(F7-F6)*(G7+G6) -> 2.1900643e-05 | I7: =MIN(10,ROUNDUP(F7*10,0)) -> 1
A8: 91516.5 | B8: 1980 | C8: =A8*B8 -> 181202670 | D8: =SUM($B$3:B8) -> 9421 | E8: =SUM($C$3:C8) -> 6.6912058e+08 | F8: =D8/$D$222 -> 0.023827228 | G8: =E8/$E$222 -> 0.0038237615 | H8: =(F8-F7)*(G8+G7) -> 3.3111276e-05 | I8: =MIN(10,ROUNDUP(F8*10,0)) -> 1
A9: 92800 | B9: 6605 | C9: =A9*B9 -> 612944000 | D9: =SUM($B$3:B9) -> 16026 | E9: =SUM($C$3:C9) -> 1.2820646e+09 | F9: =D9/$D$222 -> 0.040532338 | G9: =E9/$E$222 -> 0.0073264958 | H9: =(F9-F8)*(G9+G8) -> 0.00018626627 | I9: =MIN(10,ROUNDUP(F9*10,0)) -> 1
A10: 101064 | B10: 3176 | C10: =A10*B10 -> 320979264 | D10: =SUM($B$3:B10) -> 19202 | E10: =SUM($C$3:C10) -> 1.6030438e+09 | F10: =D10/$D$222 -> 0.048564954 | G10: =E10/$E$222 -> 0.0091607664 | H10: =(F10-F9)*(G10+G9) -> 0.00013243585 | I10: =MIN(10,ROUNDUP(F10*10,0)) -> 1
A11: 105500 | B11: 2196 | C11: =A11*B11 -> 231678000 | D11: =SUM($B$3:B11) -> 21398 | E11: =SUM($C$3:C11) -> 1.8347218e+09 | F11: =D11/$D$222 -> 0.054118992 | G11: =E11/$E$222 -> 0.010484715 | H11: =(F11-F10)*(G11+G10) -> 0.00010911175 | I11: =MIN(10,ROUNDUP(F11*10,0)) -> 1
A12: 112500 | B12: 1876 | C12: =A12*B12 -> 211050000 | D12: =SUM($B$3:B12) -> 23274 | E12: =SUM($C$3:C12) -> 2.0457718e+09 | F12: =D12/$D$222 -> 0.058863698 | G12: =E12/$E$222 -> 0.011690783 | H12: =(F12-F11)*(G12+G11) -> 0.00010521623 | I12: =MIN(10,ROUNDUP(F12*10,0)) -> 1
A13: 115539.75 | B13: 2144 | C13: =A13*B13 -> 247717224 | D13: =SUM($B$3:B13) -> 25418 | E13: =SUM($C$3:C13) -> 2.2934891e+09 | F13: =D13/$D$222 -> 0.06428622 | G13: =E13/$E$222 -> 0.01310639 | H13: =(F13-F12)*(G13+G12) -> 0.00013446321 | I13: =MIN(10,ROUNDUP(F13*10,0)) -> 1
A14: 123250 | B14: 2012 | C14: =A14*B14 -> 247979000 | D14: =SUM($B$3:B14) -> 27430 | E14: =SUM($C$3:C14) -> 2.5414681e+09 | F14: =D14/$D$222 -> 0.069374893 | G14: =E14/$E$222 -> 0.014523492 | H14: =(F14-F13)*(G14+G13) -> 0.00014059942 | I14: =MIN(10,ROUNDUP(F14*10,0)) -> 1
... A222: 2500000 | B222: 132 | C222: =A222*B222 -> 330000000 | D222: =SUM($B$3:B222) -> 395388 | E222: =SUM($C$3:C222) -> 1.7499015e+11 | F222: =D222/$D$222 -> 1 | G222: =E222/$E$222 -> 1 | H222: =(F222-F221)*(G222+G221) -> 0.00066706898 | I222: =MIN(10,ROUNDUP(F222*10,0)) -> 10
A224: Suma terminos trapezoide (Sum H) | C224: =SUM(H3:H222) -> 0.66419461
A225: COEFICIENTE DE GINI | C225: =1-C224 -> 0.33580539

Sheet Deciles_T4_2024
A1: Decil local (Corrientes) | B1: Poblacion ponderada | C1: Ingreso total ponderado | D1: IPCF promedio del decil | E1: % del ingreso total
A2: 1 | B2: =SUMIF(Gini_T4_2024!$I$3:$I$266,A2,Gini_T4_2024!$B$3:$B$266) -> 38596 | C2: =SUMIF(Gini_T4_2024!$I$3:$I$266,A2,Gini_T4_2024!$C$3:$C$266) -> 3.8383972e+09 | D2: =C2/B2 -> 99450.647 | E2: =C2/SUM($C$2:$C$11) -> 0.029014987
A3: 2 | B3: =SUMIF(Gini_T4_2024!$I$3:$I$266,A3,Gini_T4_2024!$B$3:$B$266) -> 36965 | C3: =SUMIF(Gini_T4_2024!$I$3:$I$266,A3,Gini_T4_2024!$C$3:$C$266) -> 5.7808637e+09 | D3: =C3/B3 -> 156387.49 | E3: =C3/SUM($C$2:$C$11) -> 0.043698366
A4: 3 | B4: =SUMIF(Gini_T4_2024!$I$3:$I$266,A4,Gini_T4_2024!$B$3:$B$266) -> 42211 | C4: =SUMIF(Gini_T4_2024!$I$3:$I$266,A4,Gini_T4_2024!$C$3:$C$266) -> 8.3400639e+09 | D4: =C4/B4 -> 197580.35 | E4: =C4/SUM($C$2:$C$11) -> 0.063043723
A5: 4 | B5: =SUMIF(Gini_T4_2024!$I$3:$I$266,A5,Gini_T4_2024!$B$3:$B$266) -> 37085 | C5: =SUMIF(Gini_T4_2024!$I$3:$I$266,A5,Gini_T4_2024!$C$3:$C$266) -> 8.2195753e+09 | D5: =C5/B5 -> 221641.51 | E5: =C5/SUM($C$2:$C$11) -> 0.062132932
A6: 5 | B6: =SUMIF(Gini_T4_2024!$I$3:$I$266,A6,Gini_T4_2024!$B$3:$B$266) -> 40909 | C6: =SUMIF(Gini_T4_2024!$I$3:$I$266,A6,Gini_T4_2024!$C$3:$C$266) -> 1.0256867e+10 | D6: =C6/B6 -> 250723.97 | E6: =C6/SUM($C$2:$C$11) -> 0.077533109
A7: 6 | B7: =SUMIF(Gini_T4_2024!$I$3:$I$266,A7,Gini_T4_2024!$B$3:$B$266) -> 38557 | C7: =SUMIF(Gini_T4_2024!$I$3:$I$266,A7,Gini_T4_2024!$C$3:$C$266) -> 1.1453025e+10 | D7: =C7/B7 -> 297041.4 | E7: =C7/SUM($C$2:$C$11) -> 0.086575038
A8: 7 | B8: =SUMIF(Gini_T4_2024!$I$3:$I$266,A8,Gini_T4_2024!$B$3:$B$266) -> 38919 | C8: =SUMIF(Gini_T4_2024!$I$3:$I$266,A8,Gini_T4_2024!$C$3:$C$266) -> 1.3531269e+10 | D8: =C8/B8 -> 347677.72 | E8: =C8/SUM($C$2:$C$11) -> 0.10228478
A9: 8 | B9: =SUMIF(Gini_T4_2024!$I$3:$I$266,A9,Gini_T4_2024!$B$3:$B$266) -> 40276 | C9: =SUMIF(Gini_T4_2024!$I$3:$I$266,A9,Gini_T4_2024!$C$3:$C$266) -> 1.6054009e+10 | D9: =C9/B9 -> 398599.89 | E9: =C9/SUM($C$2:$C$11) -> 0.12135453
A10: 9 | B10: =SUMIF(Gini_T4_2024!$I$3:$I$266,A10,Gini_T4_2024!$B$3:$B$266) -> 39369 | C10: =SUMIF(Gini_T4_2024!$I$3:$I$266,A10,Gini_T4_2024!$C$3:$C$266) -> 2.0121988e+10 | D10: =C10/B10 -> 511112.49 | E10: =C10/SUM($C$2:$C$11) -> 0.15210495
A11: 10 | B11: =SUMIF(Gini_T4_2024!$I$3:$I$266,A11,Gini_T4_2024!$B$3:$B$266) -> 39754 | C11: =SUMIF(Gini_T4_2024!$I$3:$I$266,A11,Gini_T4_2024!$C$3:$C$266) -> 3.4694097e+10 | D11: =C11/B11 -> 872719.66 | E11: =C11/SUM($C$2:$C$11) -> 0.26225759
A14: Brechas de ingreso entre deciles
A15: Brecha | C15: Valor
A16: D10 / D1 (decil mas rico vs mas pobre) | C16: =D11/D2 -> 8.7754045
A17: D9 / D1 | C17: =D10/D2 -> 5.1393581
A18: D10 / D5 (decil mas rico vs mediano) | C18: =D11/D6 -> 3.4807986
A19: % ingreso del decil 10 (mas rico) | C19: =E11 -> 0.26225759
A20: % ingreso del decil 1 (mas pobre) | C20: =E2 -> 0.029014987

Sheet Deciles_T4_2025
A1: Decil local (Corrientes) | B1: Poblacion ponderada | C1: Ingreso total ponderado | D1: IPCF promedio del decil | E1: % del ingreso total
A2: 1 | B2: =SUMIF(Gini_T4_2025!$I$3:$I$222,A2,Gini_T4_2025!$B$3:$B$222) -> 39463 | C2: =SUMIF(Gini_T4_2025!$I$3:$I$222,A2,Gini_T4_2025!$C$3:$C$222) -> 4.3048284e+09 | D2: =C2/B2 -> 109085.18 | E2: =C2/SUM($C$2:$C$11) -> 0.024600405
A3: 2 | B3: =SUMIF(Gini_T4_2025!$I$3:$I$222,A3,Gini_T4_2025!$B$3:$B$222) -> 37320 | C3: =SUMIF(Gini_T4_2025!$I$3:$I$222,A3,Gini_T4_2025!$C$3:$C$222) -> 6.884148e+09 | D3: =C3/B3 -> 184462.7 | E3: =C3/SUM($C$2:$C$11) -> 0.039340204
A4: 3 | B4: =SUMIF(Gini_T4_2025!$I$3:$I$222,A4,Gini_T4_2025!$B$3:$B$222) -> 39994 | C4: =SUMIF(Gini_T4_2025!$I$3:$I$222,A4,Gini_T4_2025!$C$3:$C$222) -> 9.7390103e+09 | D4: =C4/B4 -> 243511.78 | E4: =C4/SUM($C$2:$C$11) -> 0.055654621
A5: 4 | B5: =SUMIF(Gini_T4_2025!$I$3:$I$222,A5,Gini_T4_2025!$B$3:$B$222) -> 41071 | C5: =SUMIF(Gini_T4_2025!$I$3:$I$222,A5,Gini_T4_2025!$C$3:$C$222) -> 1.1980416e+10 | D5: =C5/B5 -> 291700.12 | E5: =C5/SUM($C$2:$C$11) -> 0.068463373
A6: 5 | B6: =SUMIF(Gini_T4_2025!$I$3:$I$222,A6,Gini_T4_2025!$B$3:$B$222) -> 36615 | C6: =SUMIF(Gini_T4_2025!$I$3:$I$222,A6,Gini_T4_2025!$C$3:$C$222) -> 1.2795742e+10 | D6: =C6/B6 -> 349467.21 | E6: =C6/SUM($C$2:$C$11) -> 0.073122643
A7: 6 | B7: =SUMIF(Gini_T4_2025!$I$3:$I$222,A7,Gini_T4_2025!$B$3:$B$222) -> 39880 | C7: =SUMIF(Gini_T4_2025!$I$3:$I$222,A7,Gini_T4_2025!$C$3:$C$222) -> 1.5845031e+10 | D7: =C7/B7 -> 397317.73 | E7: =C7/SUM($C$2:$C$11) -> 0.090548133
A8: 7 | B8: =SUMIF(Gini_T4_2025!$I$3:$I$222,A8,Gini_T4_2025!$B$3:$B$222) -> 41138 | C8: =SUMIF(Gini_T4_2025!$I$3:$I$222,A8,Gini_T4_2025!$C$3:$C$222) -> 1.9732155e+10 | D8: =C8/B8 -> 479657.62 | E8: =C8/SUM($C$2:$C$11) -> 0.11276152
A9: 8 | B9: =SUMIF(Gini_T4_2025!$I$3:$I$222,A9,Gini_T4_2025!$B$3:$B$222) -> 40409 | C9: =SUMIF(Gini_T4_2025!$I$3:$I$222,A9,Gini_T4_2025!$C$3:$C$222) -> 2.2840969e+10 | D9: =C9/B9 -> 565244.59 | E9: =C9/SUM($C$2:$C$11) -> 0.13052717
A10: 9 | B10: =SUMIF(Gini_T4_2025!$I$3:$I$222,A10,Gini_T4_2025!$B$3:$B$222) -> 39174 | C10: =SUMIF(Gini_T4_2025!$I$3:$I$222,A10,Gini_T4_2025!$C$3:$C$222) -> 2.7638725e+10 | D10: =C10/B10 -> 705537.46 | E10: =C10/SUM($C$2:$C$11) -> 0.15794446
A11: 10 | B11: =SUMIF(Gini_T4_2025!$I$3:$I$222,A11,Gini_T4_2025!$B$3:$B$222) -> 40324 | C11: =SUMIF(Gini_T4_2025!$I$3:$I$222,A11,Gini_T4_2025!$C$3:$C$222) -> 4.3229122e+10 | D11: =C11/B11 -> 1072044.5 | E11: =C11/SUM($C$2:$C$11) -> 0.24703747
A14: Brechas de ingreso entre deciles
A15: Brecha | C15: Valor
A16: D10 / D1 (decil mas rico vs mas pobre) | C16: =D11/D2 -> 9.8275907
A17: D9 / D1 | C17: =D10/D2 -> 6.4677665
A18: D10 / D5 (decil mas rico vs mediano) | C18: =D11/D6 -> 3.067654
A19: % ingreso del decil 10 (mas rico) | C19: =E11 -> 0.24703747
A20: % ingreso del decil 1 (mas pobre) | C20: =E2 -> 0.024600405
